2022-03-18 08:58:42,595 ERROR: Exception on / [GET] [in /usr/local/lib/python3.7/site-packages/flask/app.py:1458]
Traceback (most recent call last):
  File "/usr/local/lib/python3.7/site-packages/flask/app.py", line 2073, in wsgi_app
    response = self.full_dispatch_request()
  File "/usr/local/lib/python3.7/site-packages/flask/app.py", line 1518, in full_dispatch_request
    rv = self.handle_user_exception(e)
  File "/usr/local/lib/python3.7/site-packages/flask/app.py", line 1516, in full_dispatch_request
    rv = self.dispatch_request()
  File "/usr/local/lib/python3.7/site-packages/flask/app.py", line 1502, in dispatch_request
    return self.ensure_sync(self.view_functions[rule.endpoint])(**req.view_args)
  File "/usr/local/lib/python3.7/site-packages/flask_login/utils.py", line 272, in decorated_view
    return func(*args, **kwargs)
  File "/home/ec2-user/environment/webApp/app/main/routes.py", line 59, in index
    prev_url=prev_url)
  File "/usr/local/lib/python3.7/site-packages/flask/templating.py", line 150, in render_template
    ctx.app,
  File "/usr/local/lib/python3.7/site-packages/flask/templating.py", line 128, in _render
    rv = template.render(context)
  File "/usr/local/lib/python3.7/site-packages/jinja2/environment.py", line 1291, in render
    self.environment.handle_exception()
  File "/usr/local/lib/python3.7/site-packages/jinja2/environment.py", line 925, in handle_exception
    raise rewrite_traceback_stack(source=source)
  File "/home/ec2-user/environment/webApp/app/templates/index.html", line 2, in top-level template code
    {% import 'bootstrap/wtf.html' as wtf %}
  File "/home/ec2-user/environment/webApp/app/templates/base.html", line 1, in top-level template code
    {% extends 'bootstrap/base.html' %}
  File "/usr/local/lib/python3.7/site-packages/flask_bootstrap/templates/bootstrap/base.html", line 1, in top-level template code
    {% block doc -%}
  File "/usr/local/lib/python3.7/site-packages/flask_bootstrap/templates/bootstrap/base.html", line 4, in block 'doc'
    {%- block html %}
  File "/usr/local/lib/python3.7/site-packages/flask_bootstrap/templates/bootstrap/base.html", line 20, in block 'html'
    {% block body -%}
  File "/usr/local/lib/python3.7/site-packages/flask_bootstrap/templates/bootstrap/base.html", line 21, in block 'body'
    {% block navbar %}
  File "/home/ec2-user/environment/webApp/app/templates/base.html", line 74, in block 'navbar'
    <li class="nav-item mx-1 text-center "><a href="{{ url_for('main.adminpg') }}"class="nav-link pb-1 px-2">Admin</a></li>
  File "/usr/local/lib/python3.7/site-packages/flask/helpers.py", line 338, in url_for
    return appctx.app.handle_url_build_error(error, endpoint, values)
  File "/usr/local/lib/python3.7/site-packages/flask/helpers.py", line 326, in url_for
    endpoint, values, method=method, force_external=external
  File "/usr/local/lib/python3.7/site-packages/werkzeug/routing.py", line 2315, in build
    raise BuildError(endpoint, values, method, self)
werkzeug.routing.BuildError: Could not build url for endpoint 'main.adminpg'. Did you mean 'main.Adminpg' instead?
2022-03-18 08:59:05,975 INFO: Microblog startup [in /home/ec2-user/environment/webApp/app/__init__.py:90]
2022-03-18 09:02:59,720 INFO: Microblog startup [in /home/ec2-user/environment/webApp/app/__init__.py:92]
