2022-04-22 07:13:12,027 INFO: Microblog startup [in /home/ec2-user/environment/webApp/app/__init__.py:84]
2022-04-22 07:13:15,639 ERROR: Exception on /auth/login [GET] [in /usr/local/lib/python3.7/site-packages/flask/app.py:1458]
Traceback (most recent call last):
  File "/usr/local/lib/python3.7/site-packages/flask/app.py", line 2073, in wsgi_app
    response = self.full_dispatch_request()
  File "/usr/local/lib/python3.7/site-packages/flask/app.py", line 1518, in full_dispatch_request
    rv = self.handle_user_exception(e)
  File "/usr/local/lib/python3.7/site-packages/flask/app.py", line 1516, in full_dispatch_request
    rv = self.dispatch_request()
  File "/usr/local/lib/python3.7/site-packages/flask/app.py", line 1502, in dispatch_request
    return self.ensure_sync(self.view_functions[rule.endpoint])(**req.view_args)
  File "/home/ec2-user/environment/webApp/app/auth/routes.py", line 28, in login
    return render_template('auth/login.html', title=_('Sign In'), form=form)
  File "/usr/local/lib/python3.7/site-packages/flask/templating.py", line 150, in render_template
    ctx.app,
  File "/usr/local/lib/python3.7/site-packages/flask/templating.py", line 128, in _render
    rv = template.render(context)
  File "/usr/local/lib/python3.7/site-packages/jinja2/environment.py", line 1291, in render
    self.environment.handle_exception()
  File "/usr/local/lib/python3.7/site-packages/jinja2/environment.py", line 925, in handle_exception
    raise rewrite_traceback_stack(source=source)
  File "/home/ec2-user/environment/webApp/app/templates/auth/login.html", line 2, in top-level template code
    {% import 'bootstrap/wtf.html' as wtf %}
  File "/home/ec2-user/environment/webApp/app/templates/base.html", line 1, in top-level template code
    {% extends 'bootstrap/base.html' %}
  File "/usr/local/lib/python3.7/site-packages/flask_bootstrap/templates/bootstrap/base.html", line 1, in top-level template code
    {% block doc -%}
  File "/usr/local/lib/python3.7/site-packages/flask_bootstrap/templates/bootstrap/base.html", line 4, in block 'doc'
    {%- block html %}
  File "/usr/local/lib/python3.7/site-packages/flask_bootstrap/templates/bootstrap/base.html", line 20, in block 'html'
    {% block body -%}
  File "/usr/local/lib/python3.7/site-packages/flask_bootstrap/templates/bootstrap/base.html", line 21, in block 'body'
    {% block navbar %}
  File "/home/ec2-user/environment/webApp/app/templates/base.html", line 77, in block 'navbar'
    <li class="nav-item mx-1 text-center "><a href="{{ url_for('main.announcement') }}"class="nav-link pb-1 px-2">Announcement</a></li>
  File "/usr/local/lib/python3.7/site-packages/flask/helpers.py", line 338, in url_for
    return appctx.app.handle_url_build_error(error, endpoint, values)
  File "/usr/local/lib/python3.7/site-packages/flask/helpers.py", line 326, in url_for
    endpoint, values, method=method, force_external=external
  File "/usr/local/lib/python3.7/site-packages/werkzeug/routing.py", line 2315, in build
    raise BuildError(endpoint, values, method, self)
werkzeug.routing.BuildError: Could not build url for endpoint 'main.announcement'. Did you mean 'main.aboutus' instead?
2022-04-22 07:13:15,864 ERROR: Exception on /auth/login [GET] [in /usr/local/lib/python3.7/site-packages/flask/app.py:1458]
Traceback (most recent call last):
  File "/usr/local/lib/python3.7/site-packages/flask/app.py", line 2073, in wsgi_app
    response = self.full_dispatch_request()
  File "/usr/local/lib/python3.7/site-packages/flask/app.py", line 1518, in full_dispatch_request
    rv = self.handle_user_exception(e)
  File "/usr/local/lib/python3.7/site-packages/flask/app.py", line 1516, in full_dispatch_request
    rv = self.dispatch_request()
  File "/usr/local/lib/python3.7/site-packages/flask/app.py", line 1502, in dispatch_request
    return self.ensure_sync(self.view_functions[rule.endpoint])(**req.view_args)
  File "/home/ec2-user/environment/webApp/app/auth/routes.py", line 28, in login
    return render_template('auth/login.html', title=_('Sign In'), form=form)
  File "/usr/local/lib/python3.7/site-packages/flask/templating.py", line 150, in render_template
    ctx.app,
  File "/usr/local/lib/python3.7/site-packages/flask/templating.py", line 128, in _render
    rv = template.render(context)
  File "/usr/local/lib/python3.7/site-packages/jinja2/environment.py", line 1291, in render
    self.environment.handle_exception()
  File "/usr/local/lib/python3.7/site-packages/jinja2/environment.py", line 925, in handle_exception
    raise rewrite_traceback_stack(source=source)
  File "/home/ec2-user/environment/webApp/app/templates/auth/login.html", line 2, in top-level template code
    {% import 'bootstrap/wtf.html' as wtf %}
  File "/home/ec2-user/environment/webApp/app/templates/base.html", line 1, in top-level template code
    {% extends 'bootstrap/base.html' %}
  File "/usr/local/lib/python3.7/site-packages/flask_bootstrap/templates/bootstrap/base.html", line 1, in top-level template code
    {% block doc -%}
  File "/usr/local/lib/python3.7/site-packages/flask_bootstrap/templates/bootstrap/base.html", line 4, in block 'doc'
    {%- block html %}
  File "/usr/local/lib/python3.7/site-packages/flask_bootstrap/templates/bootstrap/base.html", line 20, in block 'html'
    {% block body -%}
  File "/usr/local/lib/python3.7/site-packages/flask_bootstrap/templates/bootstrap/base.html", line 21, in block 'body'
    {% block navbar %}
  File "/home/ec2-user/environment/webApp/app/templates/base.html", line 77, in block 'navbar'
    <li class="nav-item mx-1 text-center "><a href="{{ url_for('main.announcement') }}"class="nav-link pb-1 px-2">Announcement</a></li>
  File "/usr/local/lib/python3.7/site-packages/flask/helpers.py", line 338, in url_for
    return appctx.app.handle_url_build_error(error, endpoint, values)
  File "/usr/local/lib/python3.7/site-packages/flask/helpers.py", line 326, in url_for
    endpoint, values, method=method, force_external=external
  File "/usr/local/lib/python3.7/site-packages/werkzeug/routing.py", line 2315, in build
    raise BuildError(endpoint, values, method, self)
werkzeug.routing.BuildError: Could not build url for endpoint 'main.announcement'. Did you mean 'main.aboutus' instead?
2022-04-22 07:15:03,756 INFO: Microblog startup [in /home/ec2-user/environment/webApp/app/__init__.py:84]
2022-04-22 07:15:19,443 ERROR: Exception on /announcement [GET] [in /usr/local/lib/python3.7/site-packages/flask/app.py:1458]
Traceback (most recent call last):
  File "/usr/local/lib/python3.7/site-packages/flask/app.py", line 2073, in wsgi_app
    response = self.full_dispatch_request()
  File "/usr/local/lib/python3.7/site-packages/flask/app.py", line 1518, in full_dispatch_request
    rv = self.handle_user_exception(e)
  File "/usr/local/lib/python3.7/site-packages/flask/app.py", line 1516, in full_dispatch_request
    rv = self.dispatch_request()
  File "/usr/local/lib/python3.7/site-packages/flask/app.py", line 1502, in dispatch_request
    return self.ensure_sync(self.view_functions[rule.endpoint])(**req.view_args)
  File "/usr/local/lib/python3.7/site-packages/flask_login/utils.py", line 272, in decorated_view
    return func(*args, **kwargs)
  File "/home/ec2-user/environment/webApp/app/main/routes.py", line 372, in announcement
    return render_template('Announcement.html', form=form,Plan1=Plan1,Plan2=Plan2)
NameError: name 'Plan1' is not defined
2022-04-22 07:15:34,175 INFO: Microblog startup [in /home/ec2-user/environment/webApp/app/__init__.py:84]
2022-04-22 07:39:53,910 INFO: Microblog startup [in /home/ec2-user/environment/webApp/app/__init__.py:84]
