2022-03-15 06:47:59,186 ERROR: Exception on /admin/ [GET] [in /usr/local/lib/python3.7/site-packages/flask/app.py:1458]
Traceback (most recent call last):
  File "/usr/local/lib/python3.7/site-packages/flask/app.py", line 2073, in wsgi_app
    response = self.full_dispatch_request()
  File "/usr/local/lib/python3.7/site-packages/flask/app.py", line 1518, in full_dispatch_request
    rv = self.handle_user_exception(e)
  File "/usr/local/lib/python3.7/site-packages/flask/app.py", line 1516, in full_dispatch_request
    rv = self.dispatch_request()
  File "/usr/local/lib/python3.7/site-packages/flask/app.py", line 1502, in dispatch_request
    return self.ensure_sync(self.view_functions[rule.endpoint])(**req.view_args)
  File "/usr/local/lib/python3.7/site-packages/flask_admin/base.py", line 69, in inner
    return self._run_view(f, *args, **kwargs)
  File "/usr/local/lib/python3.7/site-packages/flask_admin/base.py", line 368, in _run_view
    return fn(self, *args, **kwargs)
  File "/usr/local/lib/python3.7/site-packages/flask_admin/base.py", line 452, in index
    return self.render(self._template)
  File "/usr/local/lib/python3.7/site-packages/flask_admin/base.py", line 308, in render
    return render_template(template, **kwargs)
  File "/usr/local/lib/python3.7/site-packages/flask/templating.py", line 150, in render_template
    ctx.app,
  File "/usr/local/lib/python3.7/site-packages/flask/templating.py", line 128, in _render
    rv = template.render(context)
  File "/usr/local/lib/python3.7/site-packages/jinja2/environment.py", line 1291, in render
    self.environment.handle_exception()
  File "/usr/local/lib/python3.7/site-packages/jinja2/environment.py", line 925, in handle_exception
    raise rewrite_traceback_stack(source=source)
  File "/usr/local/lib/python3.7/site-packages/flask_admin/templates/bootstrap2/admin/index.html", line 1, in top-level template code
    {% extends 'admin/master.html' %}
  File "/usr/local/lib/python3.7/site-packages/flask_admin/templates/bootstrap2/admin/master.html", line 1, in top-level template code
    {% extends admin_base_template %}
  File "/usr/local/lib/python3.7/site-packages/flask_admin/templates/bootstrap2/admin/base.html", line 35, in top-level template code
    {% block page_body %}
  File "/usr/local/lib/python3.7/site-packages/flask_admin/templates/bootstrap2/admin/base.html", line 42, in block 'page_body'
    {% block main_menu %}
  File "/usr/local/lib/python3.7/site-packages/flask_admin/templates/bootstrap2/admin/base.html", line 44, in block 'main_menu'
    {{ layout.menu() }}
  File "/usr/local/lib/python3.7/site-packages/jinja2/runtime.py", line 828, in _invoke
    rv = self._func(*arguments)
  File "/usr/local/lib/python3.7/site-packages/flask_admin/templates/bootstrap2/admin/layout.html", line 55, in template
    {%- if item.is_accessible() and item.is_visible() -%}
  File "/usr/local/lib/python3.7/site-packages/flask_admin/menu.py", line 126, in is_accessible
    return self._view.is_accessible()
  File "/home/ec2-user/environment/webApp/app/__init__.py", line 33, in is_accessible
    return current_user.username == "Test"
AttributeError: 'AnonymousUserMixin' object has no attribute 'username'
2022-03-18 02:51:33,992 INFO: Microblog startup [in /home/ec2-user/environment/webApp/app/__init__.py:99]
2022-03-18 03:07:38,354 INFO: Microblog startup [in /home/ec2-user/environment/webApp/app/__init__.py:99]
2022-03-18 03:07:44,002 ERROR: Exception on /auth/login [GET] [in /usr/local/lib/python3.7/site-packages/flask/app.py:1458]
Traceback (most recent call last):
  File "/usr/local/lib/python3.7/site-packages/flask/app.py", line 2073, in wsgi_app
    response = self.full_dispatch_request()
  File "/usr/local/lib/python3.7/site-packages/flask/app.py", line 1518, in full_dispatch_request
    rv = self.handle_user_exception(e)
  File "/usr/local/lib/python3.7/site-packages/flask/app.py", line 1516, in full_dispatch_request
    rv = self.dispatch_request()
  File "/usr/local/lib/python3.7/site-packages/flask/app.py", line 1502, in dispatch_request
    return self.ensure_sync(self.view_functions[rule.endpoint])(**req.view_args)
  File "/home/ec2-user/environment/webApp/app/auth/routes.py", line 28, in login
    return render_template('auth/login.html', title=_('Sign In'), form=form)
  File "/usr/local/lib/python3.7/site-packages/flask/templating.py", line 150, in render_template
    ctx.app,
  File "/usr/local/lib/python3.7/site-packages/flask/templating.py", line 128, in _render
    rv = template.render(context)
  File "/usr/local/lib/python3.7/site-packages/jinja2/environment.py", line 1291, in render
    self.environment.handle_exception()
  File "/usr/local/lib/python3.7/site-packages/jinja2/environment.py", line 925, in handle_exception
    raise rewrite_traceback_stack(source=source)
  File "/home/ec2-user/environment/webApp/app/templates/auth/login.html", line 2, in top-level template code
    {% import 'bootstrap/wtf.html' as wtf %}
  File "/home/ec2-user/environment/webApp/app/templates/base.html", line 1, in top-level template code
    {% extends 'bootstrap/base.html' %}
  File "/usr/local/lib/python3.7/site-packages/flask_bootstrap/templates/bootstrap/base.html", line 1, in top-level template code
    {% block doc -%}
  File "/usr/local/lib/python3.7/site-packages/flask_bootstrap/templates/bootstrap/base.html", line 4, in block 'doc'
    {%- block html %}
  File "/usr/local/lib/python3.7/site-packages/flask_bootstrap/templates/bootstrap/base.html", line 20, in block 'html'
    {% block body -%}
  File "/usr/local/lib/python3.7/site-packages/flask_bootstrap/templates/bootstrap/base.html", line 21, in block 'body'
    {% block navbar %}
  File "/home/ec2-user/environment/webApp/app/templates/base.html", line 74, in block 'navbar'
    <li class="nav-item mx-1 text-center "><a href="{{ url_for('main.admin') }}"class="nav-link pb-1 px-2">Admin</a></li>
  File "/usr/local/lib/python3.7/site-packages/flask/helpers.py", line 338, in url_for
    return appctx.app.handle_url_build_error(error, endpoint, values)
  File "/usr/local/lib/python3.7/site-packages/flask/helpers.py", line 326, in url_for
    endpoint, values, method=method, force_external=external
  File "/usr/local/lib/python3.7/site-packages/werkzeug/routing.py", line 2315, in build
    raise BuildError(endpoint, values, method, self)
werkzeug.routing.BuildError: Could not build url for endpoint 'main.admin'. Did you mean 'main.index' instead?
2022-03-18 03:10:16,111 INFO: Microblog startup [in /home/ec2-user/environment/webApp/app/__init__.py:99]
2022-03-18 03:10:18,628 ERROR: Exception on /auth/login [GET] [in /usr/local/lib/python3.7/site-packages/flask/app.py:1458]
Traceback (most recent call last):
  File "/usr/local/lib/python3.7/site-packages/flask/app.py", line 2073, in wsgi_app
    response = self.full_dispatch_request()
  File "/usr/local/lib/python3.7/site-packages/flask/app.py", line 1518, in full_dispatch_request
    rv = self.handle_user_exception(e)
  File "/usr/local/lib/python3.7/site-packages/flask/app.py", line 1516, in full_dispatch_request
    rv = self.dispatch_request()
  File "/usr/local/lib/python3.7/site-packages/flask/app.py", line 1502, in dispatch_request
    return self.ensure_sync(self.view_functions[rule.endpoint])(**req.view_args)
  File "/home/ec2-user/environment/webApp/app/auth/routes.py", line 28, in login
    return render_template('auth/login.html', title=_('Sign In'), form=form)
  File "/usr/local/lib/python3.7/site-packages/flask/templating.py", line 150, in render_template
    ctx.app,
  File "/usr/local/lib/python3.7/site-packages/flask/templating.py", line 128, in _render
    rv = template.render(context)
  File "/usr/local/lib/python3.7/site-packages/jinja2/environment.py", line 1291, in render
    self.environment.handle_exception()
  File "/usr/local/lib/python3.7/site-packages/jinja2/environment.py", line 925, in handle_exception
    raise rewrite_traceback_stack(source=source)
  File "/home/ec2-user/environment/webApp/app/templates/auth/login.html", line 2, in top-level template code
    {% import 'bootstrap/wtf.html' as wtf %}
  File "/home/ec2-user/environment/webApp/app/templates/base.html", line 1, in top-level template code
    {% extends 'bootstrap/base.html' %}
  File "/usr/local/lib/python3.7/site-packages/flask_bootstrap/templates/bootstrap/base.html", line 1, in top-level template code
    {% block doc -%}
  File "/usr/local/lib/python3.7/site-packages/flask_bootstrap/templates/bootstrap/base.html", line 4, in block 'doc'
    {%- block html %}
  File "/usr/local/lib/python3.7/site-packages/flask_bootstrap/templates/bootstrap/base.html", line 20, in block 'html'
    {% block body -%}
  File "/usr/local/lib/python3.7/site-packages/flask_bootstrap/templates/bootstrap/base.html", line 21, in block 'body'
    {% block navbar %}
  File "/home/ec2-user/environment/webApp/app/templates/base.html", line 74, in block 'navbar'
    <li class="nav-item mx-1 text-center "><a href="{{ url_for('main.admin') }}"class="nav-link pb-1 px-2">Admin</a></li>
  File "/usr/local/lib/python3.7/site-packages/flask/helpers.py", line 338, in url_for
    return appctx.app.handle_url_build_error(error, endpoint, values)
  File "/usr/local/lib/python3.7/site-packages/flask/helpers.py", line 326, in url_for
    endpoint, values, method=method, force_external=external
  File "/usr/local/lib/python3.7/site-packages/werkzeug/routing.py", line 2315, in build
    raise BuildError(endpoint, values, method, self)
werkzeug.routing.BuildError: Could not build url for endpoint 'main.admin'. Did you mean 'main.index' instead?
2022-03-18 03:14:35,157 INFO: Microblog startup [in /home/ec2-user/environment/webApp/app/__init__.py:99]
