2022-05-02 12:29:06,489 ERROR: Exception on /Community [POST] [in /usr/lib/python2.7/site-packages/flask/app.py:1891]
Traceback (most recent call last):
  File "/usr/lib/python2.7/site-packages/flask/app.py", line 2446, in wsgi_app
    response = self.full_dispatch_request()
  File "/usr/lib/python2.7/site-packages/flask/app.py", line 1951, in full_dispatch_request
    rv = self.handle_user_exception(e)
  File "/usr/lib/python2.7/site-packages/flask/app.py", line 1820, in handle_user_exception
    reraise(exc_type, exc_value, tb)
  File "/usr/lib/python2.7/site-packages/flask/app.py", line 1949, in full_dispatch_request
    rv = self.dispatch_request()
  File "/usr/lib/python2.7/site-packages/flask/app.py", line 1935, in dispatch_request
    return self.view_functions[rule.endpoint](**req.view_args)
  File "/usr/lib/python2.7/site-packages/flask_login/utils.py", line 272, in decorated_view
    return func(*args, **kwargs)
  File "/home/ec2-user/environment/webApp/app/main/routes.py", line 69, in Community
    db.session.commit()
  File "/usr/lib64/python2.7/site-packages/sqlalchemy/orm/scoping.py", line 162, in do
    return getattr(self.registry(), name)(*args, **kwargs)
  File "/usr/lib64/python2.7/site-packages/sqlalchemy/orm/session.py", line 1036, in commit
    self.transaction.commit()
  File "/usr/lib64/python2.7/site-packages/sqlalchemy/orm/session.py", line 503, in commit
    self._prepare_impl()
  File "/usr/lib64/python2.7/site-packages/sqlalchemy/orm/session.py", line 482, in _prepare_impl
    self.session.flush()
  File "/usr/lib64/python2.7/site-packages/sqlalchemy/orm/session.py", line 2479, in flush
    self._flush(objects)
  File "/usr/lib64/python2.7/site-packages/sqlalchemy/orm/session.py", line 2617, in _flush
    transaction.rollback(_capture_exception=True)
  File "/usr/lib64/python2.7/site-packages/sqlalchemy/util/langhelpers.py", line 68, in __exit__
    compat.reraise(exc_type, exc_value, exc_tb)
  File "/usr/lib64/python2.7/site-packages/sqlalchemy/orm/session.py", line 2577, in _flush
    flush_context.execute()
  File "/usr/lib64/python2.7/site-packages/sqlalchemy/orm/unitofwork.py", line 422, in execute
    rec.execute(self)
  File "/usr/lib64/python2.7/site-packages/sqlalchemy/orm/unitofwork.py", line 589, in execute
    uow,
  File "/usr/lib64/python2.7/site-packages/sqlalchemy/orm/persistence.py", line 245, in save_obj
    insert,
  File "/usr/lib64/python2.7/site-packages/sqlalchemy/orm/persistence.py", line 1137, in _emit_insert_statements
    statement, params
  File "/usr/lib64/python2.7/site-packages/sqlalchemy/engine/base.py", line 982, in execute
    return meth(self, multiparams, params)
  File "/usr/lib64/python2.7/site-packages/sqlalchemy/sql/elements.py", line 293, in _execute_on_connection
    return connection._execute_clauseelement(self, multiparams, params)
  File "/usr/lib64/python2.7/site-packages/sqlalchemy/engine/base.py", line 1101, in _execute_clauseelement
    distilled_params,
  File "/usr/lib64/python2.7/site-packages/sqlalchemy/engine/base.py", line 1250, in _execute_context
    e, statement, parameters, cursor, context
  File "/usr/lib64/python2.7/site-packages/sqlalchemy/engine/base.py", line 1476, in _handle_dbapi_exception
    util.raise_from_cause(sqlalchemy_exception, exc_info)
  File "/usr/lib64/python2.7/site-packages/sqlalchemy/util/compat.py", line 398, in raise_from_cause
    reraise(type(exception), exception, tb=exc_tb, cause=cause)
  File "/usr/lib64/python2.7/site-packages/sqlalchemy/engine/base.py", line 1246, in _execute_context
    cursor, statement, parameters, context
  File "/usr/lib64/python2.7/site-packages/sqlalchemy/engine/default.py", line 588, in do_execute
    cursor.execute(statement, parameters)
  File "/usr/lib/python2.7/site-packages/pymysql/cursors.py", line 163, in execute
    result = self._query(query)
  File "/usr/lib/python2.7/site-packages/pymysql/cursors.py", line 321, in _query
    conn.query(q)
  File "/usr/lib/python2.7/site-packages/pymysql/connections.py", line 505, in query
    self._affected_rows = self._read_query_result(unbuffered=unbuffered)
  File "/usr/lib/python2.7/site-packages/pymysql/connections.py", line 724, in _read_query_result
    result.read()
  File "/usr/lib/python2.7/site-packages/pymysql/connections.py", line 1069, in read
    first_packet = self.connection._read_packet()
  File "/usr/lib/python2.7/site-packages/pymysql/connections.py", line 676, in _read_packet
    packet.raise_for_error()
  File "/usr/lib/python2.7/site-packages/pymysql/protocol.py", line 223, in raise_for_error
    err.raise_mysql_exception(self._data)
  File "/usr/lib/python2.7/site-packages/pymysql/err.py", line 107, in raise_mysql_exception
    raise errorclass(errno, errval)
IntegrityError: (pymysql.err.IntegrityError) (1062, u"Duplicate entry '0' for key 'PRIMARY'")
[SQL: INSERT INTO post (body, timestamp, user_id) VALUES (%(body)s, %(timestamp)s, %(user_id)s)]
[parameters: {'body': u'Hey!', 'timestamp': datetime.datetime(2022, 5, 2, 12, 29, 6, 487311), 'user_id': 2}]
(Background on this error at: http://sqlalche.me/e/gkpj)
2022-05-02 12:36:30,376 INFO: Microblog startup [in /home/ec2-user/environment/webApp/app/__init__.py:86]
2022-05-02 12:36:48,849 ERROR: Exception on /admin/ [GET] [in /usr/lib/python2.7/site-packages/flask/app.py:1891]
Traceback (most recent call last):
  File "/usr/lib/python2.7/site-packages/flask/app.py", line 2446, in wsgi_app
    response = self.full_dispatch_request()
  File "/usr/lib/python2.7/site-packages/flask/app.py", line 1951, in full_dispatch_request
    rv = self.handle_user_exception(e)
  File "/usr/lib/python2.7/site-packages/flask/app.py", line 1820, in handle_user_exception
    reraise(exc_type, exc_value, tb)
  File "/usr/lib/python2.7/site-packages/flask/app.py", line 1949, in full_dispatch_request
    rv = self.dispatch_request()
  File "/usr/lib/python2.7/site-packages/flask/app.py", line 1935, in dispatch_request
    return self.view_functions[rule.endpoint](**req.view_args)
  File "/usr/lib/python2.7/site-packages/flask_admin/base.py", line 69, in inner
    return self._run_view(f, *args, **kwargs)
  File "/usr/lib/python2.7/site-packages/flask_admin/base.py", line 368, in _run_view
    return fn(self, *args, **kwargs)
  File "/usr/lib/python2.7/site-packages/flask_admin/base.py", line 452, in index
    return self.render(self._template)
  File "/usr/lib/python2.7/site-packages/flask_admin/base.py", line 308, in render
    return render_template(template, **kwargs)
  File "/usr/lib/python2.7/site-packages/flask/templating.py", line 140, in render_template
    ctx.app,
  File "/usr/lib/python2.7/site-packages/flask/templating.py", line 120, in _render
    rv = template.render(context)
  File "/usr/lib/python2.7/site-packages/jinja2/environment.py", line 1090, in render
    self.environment.handle_exception()
  File "/usr/lib/python2.7/site-packages/jinja2/environment.py", line 832, in handle_exception
    reraise(*rewrite_traceback_stack(source=source))
  File "/usr/lib/python2.7/site-packages/flask_admin/templates/bootstrap2/admin/index.html", line 1, in top-level template code
    {% extends 'admin/master.html' %}
  File "/usr/lib/python2.7/site-packages/flask_admin/templates/bootstrap2/admin/master.html", line 1, in top-level template code
    {% extends admin_base_template %}
  File "/usr/lib/python2.7/site-packages/flask_admin/templates/bootstrap2/admin/base.html", line 35, in top-level template code
    {% block page_body %}
  File "/usr/lib/python2.7/site-packages/flask_admin/templates/bootstrap2/admin/base.html", line 42, in block "page_body"
    {% block main_menu %}
  File "/usr/lib/python2.7/site-packages/flask_admin/templates/bootstrap2/admin/base.html", line 44, in block "main_menu"
    {{ layout.menu() }}
  File "/usr/lib/python2.7/site-packages/jinja2/runtime.py", line 679, in _invoke
    rv = self._func(*arguments)
  File "/usr/lib/python2.7/site-packages/flask_admin/templates/bootstrap2/admin/layout.html", line 40, in template
    {%- if child.is_active(admin_view) %}
  File "/usr/lib/python2.7/site-packages/flask_admin/menu.py", line 126, in is_accessible
    return self._view.is_accessible()
  File "/home/ec2-user/environment/webApp/app/main/routes.py", line 20, in is_accessible
    return checkatc1[0] == SuperAdmin
IndexError: list index out of range
