2022-05-02 12:18:08,058 ERROR: Exception on /auth/login [POST] [in /usr/lib/python2.7/site-packages/flask/app.py:1891]
Traceback (most recent call last):
  File "/usr/lib/python2.7/site-packages/flask/app.py", line 2446, in wsgi_app
    response = self.full_dispatch_request()
  File "/usr/lib/python2.7/site-packages/flask/app.py", line 1951, in full_dispatch_request
    rv = self.handle_user_exception(e)
  File "/usr/lib/python2.7/site-packages/flask/app.py", line 1820, in handle_user_exception
    reraise(exc_type, exc_value, tb)
  File "/usr/lib/python2.7/site-packages/flask/app.py", line 1949, in full_dispatch_request
    rv = self.dispatch_request()
  File "/usr/lib/python2.7/site-packages/flask/app.py", line 1935, in dispatch_request
    return self.view_functions[rule.endpoint](**req.view_args)
  File "/home/ec2-user/environment/webApp/app/auth/routes.py", line 19, in login
    user = User.query.filter_by(username=form.username.data).first()
  File "/usr/lib/python2.7/site-packages/flask_sqlalchemy/__init__.py", line 519, in __get__
    return type.query_class(mapper, session=self.sa.session())
  File "/usr/lib64/python2.7/site-packages/sqlalchemy/orm/scoping.py", line 78, in __call__
    return self.registry()
  File "/usr/lib64/python2.7/site-packages/sqlalchemy/util/_collections.py", line 1032, in __call__
    return self.registry.setdefault(key, self.createfunc())
  File "/usr/lib64/python2.7/site-packages/sqlalchemy/orm/session.py", line 3234, in __call__
    return self.class_(**local_kw)
  File "/usr/lib/python2.7/site-packages/flask_sqlalchemy/__init__.py", line 138, in __init__
    bind = options.pop('bind', None) or db.engine
  File "/usr/lib/python2.7/site-packages/flask_sqlalchemy/__init__.py", line 937, in engine
    return self.get_engine()
  File "/usr/lib/python2.7/site-packages/flask_sqlalchemy/__init__.py", line 956, in get_engine
    return connector.get_engine()
  File "/usr/lib/python2.7/site-packages/flask_sqlalchemy/__init__.py", line 561, in get_engine
    self._engine = rv = self._sa.create_engine(sa_url, options)
  File "/usr/lib/python2.7/site-packages/flask_sqlalchemy/__init__.py", line 966, in create_engine
    return sqlalchemy.create_engine(sa_url, **engine_opts)
  File "/usr/lib64/python2.7/site-packages/sqlalchemy/engine/__init__.py", line 479, in create_engine
    return strategy.create(*args, **kwargs)
  File "/usr/lib64/python2.7/site-packages/sqlalchemy/engine/strategies.py", line 87, in create
    dbapi = dialect_cls.dbapi(**dbapi_args)
  File "/usr/lib64/python2.7/site-packages/sqlalchemy/dialects/mysql/mysqldb.py", line 118, in dbapi
    return __import__("MySQLdb")
ImportError: No module named MySQLdb
2022-05-02 12:20:18,432 INFO: Microblog startup [in /home/ec2-user/environment/webApp/app/__init__.py:86]
2022-05-02 12:20:31,228 ERROR: Exception on /auth/login [POST] [in /usr/lib/python2.7/site-packages/flask/app.py:1891]
Traceback (most recent call last):
  File "/usr/lib/python2.7/site-packages/flask/app.py", line 2446, in wsgi_app
    response = self.full_dispatch_request()
  File "/usr/lib/python2.7/site-packages/flask/app.py", line 1951, in full_dispatch_request
    rv = self.handle_user_exception(e)
  File "/usr/lib/python2.7/site-packages/flask/app.py", line 1820, in handle_user_exception
    reraise(exc_type, exc_value, tb)
  File "/usr/lib/python2.7/site-packages/flask/app.py", line 1949, in full_dispatch_request
    rv = self.dispatch_request()
  File "/usr/lib/python2.7/site-packages/flask/app.py", line 1935, in dispatch_request
    return self.view_functions[rule.endpoint](**req.view_args)
  File "/home/ec2-user/environment/webApp/app/auth/routes.py", line 19, in login
    user = User.query.filter_by(username=form.username.data).first()
  File "/usr/lib/python2.7/site-packages/flask_sqlalchemy/__init__.py", line 519, in __get__
    return type.query_class(mapper, session=self.sa.session())
  File "/usr/lib64/python2.7/site-packages/sqlalchemy/orm/scoping.py", line 78, in __call__
    return self.registry()
  File "/usr/lib64/python2.7/site-packages/sqlalchemy/util/_collections.py", line 1032, in __call__
    return self.registry.setdefault(key, self.createfunc())
  File "/usr/lib64/python2.7/site-packages/sqlalchemy/orm/session.py", line 3234, in __call__
    return self.class_(**local_kw)
  File "/usr/lib/python2.7/site-packages/flask_sqlalchemy/__init__.py", line 138, in __init__
    bind = options.pop('bind', None) or db.engine
  File "/usr/lib/python2.7/site-packages/flask_sqlalchemy/__init__.py", line 937, in engine
    return self.get_engine()
  File "/usr/lib/python2.7/site-packages/flask_sqlalchemy/__init__.py", line 956, in get_engine
    return connector.get_engine()
  File "/usr/lib/python2.7/site-packages/flask_sqlalchemy/__init__.py", line 561, in get_engine
    self._engine = rv = self._sa.create_engine(sa_url, options)
  File "/usr/lib/python2.7/site-packages/flask_sqlalchemy/__init__.py", line 966, in create_engine
    return sqlalchemy.create_engine(sa_url, **engine_opts)
  File "/usr/lib64/python2.7/site-packages/sqlalchemy/engine/__init__.py", line 479, in create_engine
    return strategy.create(*args, **kwargs)
  File "/usr/lib64/python2.7/site-packages/sqlalchemy/engine/strategies.py", line 87, in create
    dbapi = dialect_cls.dbapi(**dbapi_args)
  File "/usr/lib64/python2.7/site-packages/sqlalchemy/dialects/mysql/mysqldb.py", line 118, in dbapi
    return __import__("MySQLdb")
ImportError: No module named MySQLdb
2022-05-02 12:22:23,433 INFO: Microblog startup [in /home/ec2-user/environment/webApp/app/__init__.py:86]
