2022-04-25 14:13:18,298 ERROR: Exception on /mail [POST] [in /usr/local/lib/python3.7/site-packages/flask/app.py:1458]
Traceback (most recent call last):
  File "/usr/local/lib/python3.7/site-packages/flask/app.py", line 2073, in wsgi_app
    response = self.full_dispatch_request()
  File "/usr/local/lib/python3.7/site-packages/flask/app.py", line 1518, in full_dispatch_request
    rv = self.handle_user_exception(e)
  File "/usr/local/lib/python3.7/site-packages/flask/app.py", line 1516, in full_dispatch_request
    rv = self.dispatch_request()
  File "/usr/local/lib/python3.7/site-packages/flask/app.py", line 1502, in dispatch_request
    return self.ensure_sync(self.view_functions[rule.endpoint])(**req.view_args)
  File "/home/ec2-user/environment/webApp/app/main/routes.py", line 233, in Sendmail
    mail.send(msg)
  File "/usr/local/lib/python3.7/site-packages/flask_mail.py", line 491, in send
    with self.connect() as connection:
  File "/usr/local/lib/python3.7/site-packages/flask_mail.py", line 144, in __enter__
    self.host = self.configure_host()
  File "/usr/local/lib/python3.7/site-packages/flask_mail.py", line 165, in configure_host
    host.login(self.mail.username, self.mail.password)
  File "/usr/lib64/python3.7/smtplib.py", line 730, in login
    raise last_exception
  File "/usr/lib64/python3.7/smtplib.py", line 721, in login
    initial_response_ok=initial_response_ok)
  File "/usr/lib64/python3.7/smtplib.py", line 642, in auth
    raise SMTPAuthenticationError(code, resp)
smtplib.SMTPAuthenticationError: (534, b'5.7.9 Please log in with your web browser and then try again. Learn more at\n5.7.9  https://support.google.com/mail/?p=WebLoginRequired d1-20020a05622a15c100b002f373d233d3sm40099qty.71 - gsmtp')
2022-04-25 14:17:45,773 INFO: Microblog startup [in /home/ec2-user/environment/webApp/app/__init__.py:85]
2022-04-25 14:17:49,655 ERROR: Exception on /mail [POST] [in /usr/local/lib/python3.7/site-packages/flask/app.py:1458]
Traceback (most recent call last):
  File "/usr/local/lib/python3.7/site-packages/flask/app.py", line 2073, in wsgi_app
    response = self.full_dispatch_request()
  File "/usr/local/lib/python3.7/site-packages/flask/app.py", line 1518, in full_dispatch_request
    rv = self.handle_user_exception(e)
  File "/usr/local/lib/python3.7/site-packages/flask/app.py", line 1516, in full_dispatch_request
    rv = self.dispatch_request()
  File "/usr/local/lib/python3.7/site-packages/flask/app.py", line 1502, in dispatch_request
    return self.ensure_sync(self.view_functions[rule.endpoint])(**req.view_args)
  File "/home/ec2-user/environment/webApp/app/main/routes.py", line 233, in Sendmail
    mail.send(msg)
  File "/usr/local/lib/python3.7/site-packages/flask_mail.py", line 491, in send
    with self.connect() as connection:
  File "/usr/local/lib/python3.7/site-packages/flask_mail.py", line 144, in __enter__
    self.host = self.configure_host()
  File "/usr/local/lib/python3.7/site-packages/flask_mail.py", line 165, in configure_host
    host.login(self.mail.username, self.mail.password)
  File "/usr/lib64/python3.7/smtplib.py", line 730, in login
    raise last_exception
  File "/usr/lib64/python3.7/smtplib.py", line 721, in login
    initial_response_ok=initial_response_ok)
  File "/usr/lib64/python3.7/smtplib.py", line 642, in auth
    raise SMTPAuthenticationError(code, resp)
smtplib.SMTPAuthenticationError: (534, b'5.7.9 Please log in with your web browser and then try again. Learn more at\n5.7.9  https://support.google.com/mail/?p=WebLoginRequired t186-20020a372dc3000000b0069ec8a9254esm5107049qkh.73 - gsmtp')
2022-04-25 14:31:13,678 INFO: Microblog startup [in /home/ec2-user/environment/webApp/app/__init__.py:85]
2022-04-25 14:31:21,614 ERROR: Exception on /mail [POST] [in /usr/local/lib/python3.7/site-packages/flask/app.py:1458]
Traceback (most recent call last):
  File "/usr/local/lib/python3.7/site-packages/flask/app.py", line 2073, in wsgi_app
    response = self.full_dispatch_request()
  File "/usr/local/lib/python3.7/site-packages/flask/app.py", line 1518, in full_dispatch_request
    rv = self.handle_user_exception(e)
  File "/usr/local/lib/python3.7/site-packages/flask/app.py", line 1516, in full_dispatch_request
    rv = self.dispatch_request()
  File "/usr/local/lib/python3.7/site-packages/flask/app.py", line 1502, in dispatch_request
    return self.ensure_sync(self.view_functions[rule.endpoint])(**req.view_args)
  File "/home/ec2-user/environment/webApp/app/main/routes.py", line 233, in Sendmail
    mail.send(msg)
  File "/usr/local/lib/python3.7/site-packages/flask_mail.py", line 491, in send
    with self.connect() as connection:
  File "/usr/local/lib/python3.7/site-packages/flask_mail.py", line 144, in __enter__
    self.host = self.configure_host()
  File "/usr/local/lib/python3.7/site-packages/flask_mail.py", line 165, in configure_host
    host.login(self.mail.username, self.mail.password)
  File "/usr/lib64/python3.7/smtplib.py", line 730, in login
    raise last_exception
  File "/usr/lib64/python3.7/smtplib.py", line 721, in login
    initial_response_ok=initial_response_ok)
  File "/usr/lib64/python3.7/smtplib.py", line 642, in auth
    raise SMTPAuthenticationError(code, resp)
smtplib.SMTPAuthenticationError: (534, b'5.7.9 Please log in with your web browser and then try again. Learn more at\n5.7.9  https://support.google.com/mail/?p=WebLoginRequired e13-20020a05620a12cd00b0069e908ab48dsm4917626qkl.106 - gsmtp')
2022-04-25 14:33:35,158 INFO: Microblog startup [in /home/ec2-user/environment/webApp/app/__init__.py:85]
2022-04-25 14:33:42,973 ERROR: Exception on /Sendmail [POST] [in /usr/local/lib/python3.7/site-packages/flask/app.py:1458]
Traceback (most recent call last):
  File "/usr/local/lib/python3.7/site-packages/flask/app.py", line 2073, in wsgi_app
    response = self.full_dispatch_request()
  File "/usr/local/lib/python3.7/site-packages/flask/app.py", line 1518, in full_dispatch_request
    rv = self.handle_user_exception(e)
  File "/usr/local/lib/python3.7/site-packages/flask/app.py", line 1516, in full_dispatch_request
    rv = self.dispatch_request()
  File "/usr/local/lib/python3.7/site-packages/flask/app.py", line 1502, in dispatch_request
    return self.ensure_sync(self.view_functions[rule.endpoint])(**req.view_args)
  File "/home/ec2-user/environment/webApp/app/main/routes.py", line 233, in Sendmail
    mail.send(msg)
  File "/usr/local/lib/python3.7/site-packages/flask_mail.py", line 491, in send
    with self.connect() as connection:
  File "/usr/local/lib/python3.7/site-packages/flask_mail.py", line 144, in __enter__
    self.host = self.configure_host()
  File "/usr/local/lib/python3.7/site-packages/flask_mail.py", line 165, in configure_host
    host.login(self.mail.username, self.mail.password)
  File "/usr/lib64/python3.7/smtplib.py", line 730, in login
    raise last_exception
  File "/usr/lib64/python3.7/smtplib.py", line 721, in login
    initial_response_ok=initial_response_ok)
  File "/usr/lib64/python3.7/smtplib.py", line 642, in auth
    raise SMTPAuthenticationError(code, resp)
smtplib.SMTPAuthenticationError: (534, b'5.7.9 Please log in with your web browser and then try again. Learn more at\n5.7.9  https://support.google.com/mail/?p=WebLoginRequired t193-20020a3746ca000000b0069f70bc6cf5sm253912qka.1 - gsmtp')
2022-04-25 14:34:20,145 INFO: Microblog startup [in /home/ec2-user/environment/webApp/app/__init__.py:85]
2022-04-25 14:34:28,371 ERROR: Exception on /Sendmail [POST] [in /usr/local/lib/python3.7/site-packages/flask/app.py:1458]
Traceback (most recent call last):
  File "/usr/local/lib/python3.7/site-packages/flask/app.py", line 2073, in wsgi_app
    response = self.full_dispatch_request()
  File "/usr/local/lib/python3.7/site-packages/flask/app.py", line 1518, in full_dispatch_request
    rv = self.handle_user_exception(e)
  File "/usr/local/lib/python3.7/site-packages/flask/app.py", line 1516, in full_dispatch_request
    rv = self.dispatch_request()
  File "/usr/local/lib/python3.7/site-packages/flask/app.py", line 1502, in dispatch_request
    return self.ensure_sync(self.view_functions[rule.endpoint])(**req.view_args)
  File "/home/ec2-user/environment/webApp/app/main/routes.py", line 233, in Sendmail
    mail.send(msg)
  File "/usr/local/lib/python3.7/site-packages/flask_mail.py", line 491, in send
    with self.connect() as connection:
  File "/usr/local/lib/python3.7/site-packages/flask_mail.py", line 144, in __enter__
    self.host = self.configure_host()
  File "/usr/local/lib/python3.7/site-packages/flask_mail.py", line 165, in configure_host
    host.login(self.mail.username, self.mail.password)
  File "/usr/lib64/python3.7/smtplib.py", line 730, in login
    raise last_exception
  File "/usr/lib64/python3.7/smtplib.py", line 721, in login
    initial_response_ok=initial_response_ok)
  File "/usr/lib64/python3.7/smtplib.py", line 642, in auth
    raise SMTPAuthenticationError(code, resp)
smtplib.SMTPAuthenticationError: (534, b'5.7.9 Please log in with your web browser and then try again. Learn more at\n5.7.9  https://support.google.com/mail/?p=WebLoginRequired j12-20020a05622a038c00b002f340aeffb3sm6340496qtx.85 - gsmtp')
2022-04-25 14:36:07,891 INFO: Microblog startup [in /home/ec2-user/environment/webApp/app/__init__.py:93]
