2022-04-22 08:32:25,411 ERROR: Exception on /aboutus [GET] [in /usr/local/lib/python3.7/site-packages/flask/app.py:1458]
Traceback (most recent call last):
  File "/usr/local/lib64/python3.7/site-packages/sqlalchemy/engine/base.py", line 1246, in _execute_context
    cursor, statement, parameters, context
  File "/usr/local/lib64/python3.7/site-packages/sqlalchemy/engine/default.py", line 588, in do_execute
    cursor.execute(statement, parameters)
  File "/usr/local/lib64/python3.7/site-packages/MySQLdb/cursors.py", line 206, in execute
    res = self._query(query)
  File "/usr/local/lib64/python3.7/site-packages/MySQLdb/cursors.py", line 319, in _query
    db.query(q)
  File "/usr/local/lib64/python3.7/site-packages/MySQLdb/connections.py", line 254, in query
    _mysql.connection.query(self, query)
MySQLdb._exceptions.ProgrammingError: (1146, "Table 'FYP_DATABASE.support_tel' doesn't exist")

The above exception was the direct cause of the following exception:

Traceback (most recent call last):
  File "/usr/local/lib/python3.7/site-packages/flask/app.py", line 2073, in wsgi_app
    response = self.full_dispatch_request()
  File "/usr/local/lib/python3.7/site-packages/flask/app.py", line 1518, in full_dispatch_request
    rv = self.handle_user_exception(e)
  File "/usr/local/lib/python3.7/site-packages/flask/app.py", line 1516, in full_dispatch_request
    rv = self.dispatch_request()
  File "/usr/local/lib/python3.7/site-packages/flask/app.py", line 1502, in dispatch_request
    return self.ensure_sync(self.view_functions[rule.endpoint])(**req.view_args)
  File "/usr/local/lib/python3.7/site-packages/flask_login/utils.py", line 272, in decorated_view
    return func(*args, **kwargs)
  File "/home/ec2-user/environment/webApp/app/main/routes.py", line 344, in aboutus
    Tel1 = SupportTel.query.get(11112222)
  File "/usr/local/lib64/python3.7/site-packages/sqlalchemy/orm/query.py", line 1004, in get
    return self._get_impl(ident, loading.load_on_pk_identity)
  File "/usr/local/lib64/python3.7/site-packages/sqlalchemy/orm/query.py", line 1116, in _get_impl
    return db_load_fn(self, primary_key_identity)
  File "/usr/local/lib64/python3.7/site-packages/sqlalchemy/orm/loading.py", line 284, in load_on_pk_identity
    return q.one()
  File "/usr/local/lib64/python3.7/site-packages/sqlalchemy/orm/query.py", line 3347, in one
    ret = self.one_or_none()
  File "/usr/local/lib64/python3.7/site-packages/sqlalchemy/orm/query.py", line 3316, in one_or_none
    ret = list(self)
  File "/usr/local/lib64/python3.7/site-packages/sqlalchemy/orm/query.py", line 3389, in __iter__
    return self._execute_and_instances(context)
  File "/usr/local/lib64/python3.7/site-packages/sqlalchemy/orm/query.py", line 3414, in _execute_and_instances
    result = conn.execute(querycontext.statement, self._params)
  File "/usr/local/lib64/python3.7/site-packages/sqlalchemy/engine/base.py", line 982, in execute
    return meth(self, multiparams, params)
  File "/usr/local/lib64/python3.7/site-packages/sqlalchemy/sql/elements.py", line 293, in _execute_on_connection
    return connection._execute_clauseelement(self, multiparams, params)
  File "/usr/local/lib64/python3.7/site-packages/sqlalchemy/engine/base.py", line 1101, in _execute_clauseelement
    distilled_params,
  File "/usr/local/lib64/python3.7/site-packages/sqlalchemy/engine/base.py", line 1250, in _execute_context
    e, statement, parameters, cursor, context
  File "/usr/local/lib64/python3.7/site-packages/sqlalchemy/engine/base.py", line 1476, in _handle_dbapi_exception
    util.raise_from_cause(sqlalchemy_exception, exc_info)
  File "/usr/local/lib64/python3.7/site-packages/sqlalchemy/util/compat.py", line 398, in raise_from_cause
    reraise(type(exception), exception, tb=exc_tb, cause=cause)
  File "/usr/local/lib64/python3.7/site-packages/sqlalchemy/util/compat.py", line 152, in reraise
    raise value.with_traceback(tb)
  File "/usr/local/lib64/python3.7/site-packages/sqlalchemy/engine/base.py", line 1246, in _execute_context
    cursor, statement, parameters, context
  File "/usr/local/lib64/python3.7/site-packages/sqlalchemy/engine/default.py", line 588, in do_execute
    cursor.execute(statement, parameters)
  File "/usr/local/lib64/python3.7/site-packages/MySQLdb/cursors.py", line 206, in execute
    res = self._query(query)
  File "/usr/local/lib64/python3.7/site-packages/MySQLdb/cursors.py", line 319, in _query
    db.query(q)
  File "/usr/local/lib64/python3.7/site-packages/MySQLdb/connections.py", line 254, in query
    _mysql.connection.query(self, query)
sqlalchemy.exc.ProgrammingError: (MySQLdb._exceptions.ProgrammingError) (1146, "Table 'FYP_DATABASE.support_tel' doesn't exist")
[SQL: SELECT support_tel.`Telno` AS `support_tel_Telno`, support_tel.`Service` AS `support_tel_Service` 
FROM support_tel 
WHERE support_tel.`Telno` = %s]
[parameters: (11112222,)]
(Background on this error at: http://sqlalche.me/e/f405)
