2022-05-02 13:01:27,256 ERROR: Exception on /Community [GET] [in /usr/lib/python2.7/site-packages/flask/app.py:1891]
Traceback (most recent call last):
  File "/usr/lib/python2.7/site-packages/flask/app.py", line 2446, in wsgi_app
    response = self.full_dispatch_request()
  File "/usr/lib/python2.7/site-packages/flask/app.py", line 1951, in full_dispatch_request
    rv = self.handle_user_exception(e)
  File "/usr/lib/python2.7/site-packages/flask/app.py", line 1820, in handle_user_exception
    reraise(exc_type, exc_value, tb)
  File "/usr/lib/python2.7/site-packages/flask/app.py", line 1949, in full_dispatch_request
    rv = self.dispatch_request()
  File "/usr/lib/python2.7/site-packages/flask/app.py", line 1935, in dispatch_request
    return self.view_functions[rule.endpoint](**req.view_args)
  File "/usr/lib/python2.7/site-packages/flask_login/utils.py", line 272, in decorated_view
    return func(*args, **kwargs)
  File "/home/ec2-user/environment/webApp/app/main/routes.py", line 73, in Community
    posts = current_user.followed_posts().paginate(
  File "/home/ec2-user/environment/webApp/app/models.py", line 167, in followed_posts
    return followed.union(own).order_by(Post.timestamp.desc())
AttributeError: 'list' object has no attribute 'union'
2022-05-02 13:02:31,895 INFO: Microblog startup [in /home/ec2-user/environment/webApp/app/__init__.py:86]
2022-05-02 13:04:06,126 INFO: Microblog startup [in /home/ec2-user/environment/webApp/app/__init__.py:86]
2022-05-02 13:07:36,849 INFO: Microblog startup [in /home/ec2-user/environment/webApp/app/__init__.py:86]
