2022-04-25 14:36:21,150 ERROR: Exception on /Sendmail [POST] [in /usr/local/lib/python3.7/site-packages/flask/app.py:1458]
Traceback (most recent call last):
  File "/usr/local/lib/python3.7/site-packages/flask/app.py", line 2073, in wsgi_app
    response = self.full_dispatch_request()
  File "/usr/local/lib/python3.7/site-packages/flask/app.py", line 1518, in full_dispatch_request
    rv = self.handle_user_exception(e)
  File "/usr/local/lib/python3.7/site-packages/flask/app.py", line 1516, in full_dispatch_request
    rv = self.dispatch_request()
  File "/usr/local/lib/python3.7/site-packages/flask/app.py", line 1502, in dispatch_request
    return self.ensure_sync(self.view_functions[rule.endpoint])(**req.view_args)
  File "/home/ec2-user/environment/webApp/app/main/routes.py", line 233, in Sendmail
    mail.send(msg)
  File "/usr/local/lib/python3.7/site-packages/flask_mail.py", line 491, in send
    with self.connect() as connection:
  File "/usr/local/lib/python3.7/site-packages/flask_mail.py", line 144, in __enter__
    self.host = self.configure_host()
  File "/usr/local/lib/python3.7/site-packages/flask_mail.py", line 165, in configure_host
    host.login(self.mail.username, self.mail.password)
  File "/usr/lib64/python3.7/smtplib.py", line 730, in login
    raise last_exception
  File "/usr/lib64/python3.7/smtplib.py", line 721, in login
    initial_response_ok=initial_response_ok)
  File "/usr/lib64/python3.7/smtplib.py", line 642, in auth
    raise SMTPAuthenticationError(code, resp)
smtplib.SMTPAuthenticationError: (534, b'5.7.9 Please log in with your web browser and then try again. Learn more at\n5.7.9  https://support.google.com/mail/?p=WebLoginRequired j2-20020ac85c42000000b002f36764a3c4sm2332812qtj.32 - gsmtp')
2022-04-25 14:37:09,204 INFO: Microblog startup [in /home/ec2-user/environment/webApp/app/__init__.py:93]
2022-04-25 14:39:41,233 INFO: Microblog startup [in /home/ec2-user/environment/webApp/app/__init__.py:93]
2022-04-25 14:41:28,223 INFO: Microblog startup [in /home/ec2-user/environment/webApp/app/__init__.py:93]
2022-04-25 14:44:53,839 INFO: Microblog startup [in /home/ec2-user/environment/webApp/app/__init__.py:93]
2022-04-25 14:46:37,698 INFO: Microblog startup [in /home/ec2-user/environment/webApp/app/__init__.py:93]
2022-04-25 14:46:47,153 INFO: Microblog startup [in /home/ec2-user/environment/webApp/app/__init__.py:93]
2022-04-25 14:48:36,010 INFO: Microblog startup [in /home/ec2-user/environment/webApp/app/__init__.py:87]
2022-04-25 14:48:43,177 ERROR: Exception on /Sendmail [POST] [in /usr/local/lib/python3.7/site-packages/flask/app.py:1458]
Traceback (most recent call last):
  File "/usr/local/lib/python3.7/site-packages/flask/app.py", line 2073, in wsgi_app
    response = self.full_dispatch_request()
  File "/usr/local/lib/python3.7/site-packages/flask/app.py", line 1518, in full_dispatch_request
    rv = self.handle_user_exception(e)
  File "/usr/local/lib/python3.7/site-packages/flask/app.py", line 1516, in full_dispatch_request
    rv = self.dispatch_request()
  File "/usr/local/lib/python3.7/site-packages/flask/app.py", line 1502, in dispatch_request
    return self.ensure_sync(self.view_functions[rule.endpoint])(**req.view_args)
  File "/home/ec2-user/environment/webApp/app/main/routes.py", line 233, in Sendmail
    mail.send(msg)
  File "/usr/local/lib/python3.7/site-packages/flask_mail.py", line 491, in send
    with self.connect() as connection:
  File "/usr/local/lib/python3.7/site-packages/flask_mail.py", line 144, in __enter__
    self.host = self.configure_host()
  File "/usr/local/lib/python3.7/site-packages/flask_mail.py", line 165, in configure_host
    host.login(self.mail.username, self.mail.password)
  File "/usr/lib64/python3.7/smtplib.py", line 730, in login
    raise last_exception
  File "/usr/lib64/python3.7/smtplib.py", line 721, in login
    initial_response_ok=initial_response_ok)
  File "/usr/lib64/python3.7/smtplib.py", line 642, in auth
    raise SMTPAuthenticationError(code, resp)
smtplib.SMTPAuthenticationError: (534, b'5.7.14 <https://accounts.google.com/signin/continue?sarp=1&scc=1&plt=AKgnsbs\n5.7.14 n1BjWdFPyKMKjhVQ6DCNGgKmsbYYW7DcacAxPx4-fKHCaqB56hJIsZQzpx8L6ycRsaUjs\n5.7.14 9bJDz-bEahv9A8RfK9Yv6vTa2uKv_LstMIMYduRjxQGc9xzJPTncF-VQaOhE9q81>\n5.7.14 Please log in via your web browser and then try again.\n5.7.14  Learn more at\n5.7.14  https://support.google.com/mail/answer/78754 d17-20020ac85d91000000b002f365edfd21sm2647827qtx.83 - gsmtp')
2022-04-25 14:51:19,032 INFO: Microblog startup [in /home/ec2-user/environment/webApp/app/__init__.py:87]
2022-04-25 14:51:25,880 ERROR: Exception on /Sendmail [POST] [in /usr/local/lib/python3.7/site-packages/flask/app.py:1458]
Traceback (most recent call last):
  File "/usr/local/lib/python3.7/site-packages/flask/app.py", line 2073, in wsgi_app
    response = self.full_dispatch_request()
  File "/usr/local/lib/python3.7/site-packages/flask/app.py", line 1518, in full_dispatch_request
    rv = self.handle_user_exception(e)
  File "/usr/local/lib/python3.7/site-packages/flask/app.py", line 1516, in full_dispatch_request
    rv = self.dispatch_request()
  File "/usr/local/lib/python3.7/site-packages/flask/app.py", line 1502, in dispatch_request
    return self.ensure_sync(self.view_functions[rule.endpoint])(**req.view_args)
  File "/home/ec2-user/environment/webApp/app/main/routes.py", line 233, in Sendmail
    mail.send(msg)
  File "/usr/local/lib/python3.7/site-packages/flask_mail.py", line 491, in send
    with self.connect() as connection:
  File "/usr/local/lib/python3.7/site-packages/flask_mail.py", line 144, in __enter__
    self.host = self.configure_host()
  File "/usr/local/lib/python3.7/site-packages/flask_mail.py", line 165, in configure_host
    host.login(self.mail.username, self.mail.password)
  File "/usr/lib64/python3.7/smtplib.py", line 730, in login
    raise last_exception
  File "/usr/lib64/python3.7/smtplib.py", line 721, in login
    initial_response_ok=initial_response_ok)
  File "/usr/lib64/python3.7/smtplib.py", line 642, in auth
    raise SMTPAuthenticationError(code, resp)
smtplib.SMTPAuthenticationError: (534, b'5.7.14 <https://accounts.google.com/signin/continue?sarp=1&scc=1&plt=AKgnsbt\n5.7.14 SbKOoFVkD-gBaQdkNTxjMhRnWC6NSIo51rTviHVCj4lVD1Vh3BrbpdRgKvN5tqku5hCsg\n5.7.14 H9aHsn6-KvVp82TbSa4rOSJpDF3HGW76h6pF_lpc7bUL6xkJZcJamw3Hdhe8W0y->\n5.7.14 Please log in via your web browser and then try again.\n5.7.14  Learn more at\n5.7.14  https://support.google.com/mail/answer/78754 i68-20020a375447000000b006809e0adfffsm5172148qkb.25 - gsmtp')
2022-04-25 14:54:38,201 INFO: Microblog startup [in /home/ec2-user/environment/webApp/app/__init__.py:87]
2022-04-25 14:55:01,135 ERROR: Exception on /Sendmail [POST] [in /usr/local/lib/python3.7/site-packages/flask/app.py:1458]
Traceback (most recent call last):
  File "/usr/local/lib/python3.7/site-packages/flask/app.py", line 2073, in wsgi_app
    response = self.full_dispatch_request()
  File "/usr/local/lib/python3.7/site-packages/flask/app.py", line 1518, in full_dispatch_request
    rv = self.handle_user_exception(e)
  File "/usr/local/lib/python3.7/site-packages/flask/app.py", line 1516, in full_dispatch_request
    rv = self.dispatch_request()
  File "/usr/local/lib/python3.7/site-packages/flask/app.py", line 1502, in dispatch_request
    return self.ensure_sync(self.view_functions[rule.endpoint])(**req.view_args)
  File "/home/ec2-user/environment/webApp/app/main/routes.py", line 233, in Sendmail
    mail.send(msg)
  File "/usr/local/lib/python3.7/site-packages/flask_mail.py", line 491, in send
    with self.connect() as connection:
  File "/usr/local/lib/python3.7/site-packages/flask_mail.py", line 144, in __enter__
    self.host = self.configure_host()
  File "/usr/local/lib/python3.7/site-packages/flask_mail.py", line 165, in configure_host
    host.login(self.mail.username, self.mail.password)
  File "/usr/lib64/python3.7/smtplib.py", line 730, in login
    raise last_exception
  File "/usr/lib64/python3.7/smtplib.py", line 721, in login
    initial_response_ok=initial_response_ok)
  File "/usr/lib64/python3.7/smtplib.py", line 642, in auth
    raise SMTPAuthenticationError(code, resp)
smtplib.SMTPAuthenticationError: (534, b'5.7.14 <https://accounts.google.com/signin/continue?sarp=1&scc=1&plt=AKgnsbt\n5.7.14 cJ1J_d0DQYgjPOgCVazZkYtDhKHJXUAntJnJ1DHsslcNY4EiAxwMRaxWLwmcev3qZu4iO\n5.7.14 a4FhhM7L7aOwNIymYAoD4B5JJLfQ7SqYidzdWPaCEA8F4x0hy35EWot4iJAjkaJc>\n5.7.14 Please log in via your web browser and then try again.\n5.7.14  Learn more at\n5.7.14  https://support.google.com/mail/answer/78754 k20-20020a05622a03d400b002ec16d2694fsm6413888qtx.39 - gsmtp')
