2022-03-04 05:00:38,130 ERROR: Exception on /upload [POST] [in /usr/lib/python2.7/site-packages/flask/app.py:1891]
Traceback (most recent call last):
  File "/usr/lib/python2.7/site-packages/flask/app.py", line 2446, in wsgi_app
    response = self.full_dispatch_request()
  File "/usr/lib/python2.7/site-packages/flask/app.py", line 1951, in full_dispatch_request
    rv = self.handle_user_exception(e)
  File "/usr/lib/python2.7/site-packages/flask/app.py", line 1820, in handle_user_exception
    reraise(exc_type, exc_value, tb)
  File "/usr/lib/python2.7/site-packages/flask/app.py", line 1949, in full_dispatch_request
    rv = self.dispatch_request()
  File "/usr/lib/python2.7/site-packages/flask/app.py", line 1935, in dispatch_request
    return self.view_functions[rule.endpoint](**req.view_args)
  File "/home/ec2-user/environment/webApp/app/main/routes.py", line 308, in upload
    return render_template("s3_send_image",msg =msg)
  File "/usr/lib/python2.7/site-packages/flask/templating.py", line 138, in render_template
    ctx.app.jinja_env.get_or_select_template(template_name_or_list),
  File "/usr/lib/python2.7/site-packages/jinja2/environment.py", line 930, in get_or_select_template
    return self.get_template(template_name_or_list, parent, globals)
  File "/usr/lib/python2.7/site-packages/jinja2/environment.py", line 883, in get_template
    return self._load_template(name, self.make_globals(globals))
  File "/usr/lib/python2.7/site-packages/jinja2/environment.py", line 857, in _load_template
    template = self.loader.load(self, name, globals)
  File "/usr/lib/python2.7/site-packages/jinja2/loaders.py", line 117, in load
    source, filename, uptodate = self.get_source(environment, name)
  File "/usr/lib/python2.7/site-packages/flask/templating.py", line 60, in get_source
    return self._get_source_fast(environment, template)
  File "/usr/lib/python2.7/site-packages/flask/templating.py", line 89, in _get_source_fast
    raise TemplateNotFound(template)
TemplateNotFound: s3_send_image
2022-03-04 05:02:57,937 INFO: Microblog startup [in /home/ec2-user/environment/webApp/app/__init__.py:74]
2022-03-04 15:47:37,453 INFO: Microblog startup [in /home/ec2-user/environment/webApp/app/__init__.py:74]
2022-03-04 15:51:27,495 INFO: Microblog startup [in /home/ec2-user/environment/webApp/app/__init__.py:74]
2022-03-04 15:53:13,929 ERROR: Exception on /upload [POST] [in /usr/lib/python2.7/site-packages/flask/app.py:1891]
Traceback (most recent call last):
  File "/usr/lib/python2.7/site-packages/flask/app.py", line 2446, in wsgi_app
    response = self.full_dispatch_request()
  File "/usr/lib/python2.7/site-packages/flask/app.py", line 1951, in full_dispatch_request
    rv = self.handle_user_exception(e)
  File "/usr/lib/python2.7/site-packages/flask/app.py", line 1820, in handle_user_exception
    reraise(exc_type, exc_value, tb)
  File "/usr/lib/python2.7/site-packages/flask/app.py", line 1949, in full_dispatch_request
    rv = self.dispatch_request()
  File "/usr/lib/python2.7/site-packages/flask/app.py", line 1935, in dispatch_request
    return self.view_functions[rule.endpoint](**req.view_args)
  File "/home/ec2-user/environment/webApp/app/main/routes.py", line 304, in upload
    Key = filename
  File "/usr/lib/python2.7/site-packages/boto3/s3/inject.py", line 131, in upload_file
    extra_args=ExtraArgs, callback=Callback)
  File "/usr/lib/python2.7/site-packages/boto3/s3/transfer.py", line 279, in upload_file
    future.result()
  File "/usr/lib/python2.7/site-packages/s3transfer/futures.py", line 106, in result
    return self._coordinator.result()
  File "/usr/lib/python2.7/site-packages/s3transfer/futures.py", line 265, in result
    raise self._exception
OSError: [Errno 2] No such file or directory: 'god_face.png'
2022-03-04 15:53:55,511 INFO: Microblog startup [in /home/ec2-user/environment/webApp/app/__init__.py:74]
2022-03-04 15:54:55,876 ERROR: Exception on /upload [POST] [in /usr/lib/python2.7/site-packages/flask/app.py:1891]
Traceback (most recent call last):
  File "/usr/lib/python2.7/site-packages/flask/app.py", line 2446, in wsgi_app
    response = self.full_dispatch_request()
  File "/usr/lib/python2.7/site-packages/flask/app.py", line 1951, in full_dispatch_request
    rv = self.handle_user_exception(e)
  File "/usr/lib/python2.7/site-packages/flask/app.py", line 1820, in handle_user_exception
    reraise(exc_type, exc_value, tb)
  File "/usr/lib/python2.7/site-packages/flask/app.py", line 1949, in full_dispatch_request
    rv = self.dispatch_request()
  File "/usr/lib/python2.7/site-packages/flask/app.py", line 1935, in dispatch_request
    return self.view_functions[rule.endpoint](**req.view_args)
  File "/home/ec2-user/environment/webApp/app/main/routes.py", line 304, in upload
    Key = filename
  File "/usr/lib/python2.7/site-packages/boto3/s3/inject.py", line 131, in upload_file
    extra_args=ExtraArgs, callback=Callback)
  File "/usr/lib/python2.7/site-packages/boto3/s3/transfer.py", line 287, in upload_file
    filename, '/'.join([bucket, key]), e))
S3UploadFailedError: Failed to upload god_face.png to fype03/god_face.png: An error occurred (ExpiredToken) when calling the PutObject operation: The provided token has expired.
2022-03-04 15:56:09,197 INFO: Microblog startup [in /home/ec2-user/environment/webApp/app/__init__.py:74]
2022-03-04 15:56:52,729 ERROR: Exception on /upload [POST] [in /usr/lib/python2.7/site-packages/flask/app.py:1891]
Traceback (most recent call last):
  File "/usr/lib/python2.7/site-packages/flask/app.py", line 2446, in wsgi_app
    response = self.full_dispatch_request()
  File "/usr/lib/python2.7/site-packages/flask/app.py", line 1951, in full_dispatch_request
    rv = self.handle_user_exception(e)
  File "/usr/lib/python2.7/site-packages/flask/app.py", line 1820, in handle_user_exception
    reraise(exc_type, exc_value, tb)
  File "/usr/lib/python2.7/site-packages/flask/app.py", line 1949, in full_dispatch_request
    rv = self.dispatch_request()
  File "/usr/lib/python2.7/site-packages/flask/app.py", line 1935, in dispatch_request
    return self.view_functions[rule.endpoint](**req.view_args)
  File "/home/ec2-user/environment/webApp/app/main/routes.py", line 304, in upload
    Key = filename
  File "/usr/lib/python2.7/site-packages/boto3/s3/inject.py", line 131, in upload_file
    extra_args=ExtraArgs, callback=Callback)
  File "/usr/lib/python2.7/site-packages/boto3/s3/transfer.py", line 287, in upload_file
    filename, '/'.join([bucket, key]), e))
S3UploadFailedError: Failed to upload god_face.png to fype03/god_face.png: An error occurred (InvalidAccessKeyId) when calling the PutObject operation: The AWS Access Key Id you provided does not exist in our records.
2022-03-04 19:13:04,110 INFO: Microblog startup [in /home/ec2-user/environment/webApp/app/__init__.py:74]
2022-03-04 19:14:59,280 ERROR: Exception on /upload [POST] [in /usr/lib/python2.7/site-packages/flask/app.py:1891]
Traceback (most recent call last):
  File "/usr/lib/python2.7/site-packages/flask/app.py", line 2446, in wsgi_app
    response = self.full_dispatch_request()
  File "/usr/lib/python2.7/site-packages/flask/app.py", line 1951, in full_dispatch_request
    rv = self.handle_user_exception(e)
  File "/usr/lib/python2.7/site-packages/flask/app.py", line 1820, in handle_user_exception
    reraise(exc_type, exc_value, tb)
  File "/usr/lib/python2.7/site-packages/flask/app.py", line 1949, in full_dispatch_request
    rv = self.dispatch_request()
  File "/usr/lib/python2.7/site-packages/flask/app.py", line 1935, in dispatch_request
    return self.view_functions[rule.endpoint](**req.view_args)
  File "/home/ec2-user/environment/webApp/app/main/routes.py", line 294, in upload
    aws_access_key_id= credentials.access_key,
AttributeError: 'NoneType' object has no attribute 'access_key'
2022-03-04 19:21:19,084 INFO: Microblog startup [in /home/ec2-user/environment/webApp/app/__init__.py:74]
2022-03-04 19:21:39,501 ERROR: Exception on /upload [POST] [in /usr/lib/python2.7/site-packages/flask/app.py:1891]
Traceback (most recent call last):
  File "/usr/lib/python2.7/site-packages/flask/app.py", line 2446, in wsgi_app
    response = self.full_dispatch_request()
  File "/usr/lib/python2.7/site-packages/flask/app.py", line 1951, in full_dispatch_request
    rv = self.handle_user_exception(e)
  File "/usr/lib/python2.7/site-packages/flask/app.py", line 1820, in handle_user_exception
    reraise(exc_type, exc_value, tb)
  File "/usr/lib/python2.7/site-packages/flask/app.py", line 1949, in full_dispatch_request
    rv = self.dispatch_request()
  File "/usr/lib/python2.7/site-packages/flask/app.py", line 1935, in dispatch_request
    return self.view_functions[rule.endpoint](**req.view_args)
  File "/home/ec2-user/environment/webApp/app/main/routes.py", line 294, in upload
    aws_access_key_id= credentials.access_key,
AttributeError: 'NoneType' object has no attribute 'access_key'
2022-03-04 19:24:50,576 INFO: Microblog startup [in /home/ec2-user/environment/webApp/app/__init__.py:74]
2022-03-04 19:25:15,398 ERROR: Exception on /upload [POST] [in /usr/lib/python2.7/site-packages/flask/app.py:1891]
Traceback (most recent call last):
  File "/usr/lib/python2.7/site-packages/flask/app.py", line 2446, in wsgi_app
    response = self.full_dispatch_request()
  File "/usr/lib/python2.7/site-packages/flask/app.py", line 1951, in full_dispatch_request
    rv = self.handle_user_exception(e)
  File "/usr/lib/python2.7/site-packages/flask/app.py", line 1820, in handle_user_exception
    reraise(exc_type, exc_value, tb)
  File "/usr/lib/python2.7/site-packages/flask/app.py", line 1949, in full_dispatch_request
    rv = self.dispatch_request()
  File "/usr/lib/python2.7/site-packages/flask/app.py", line 1935, in dispatch_request
    return self.view_functions[rule.endpoint](**req.view_args)
  File "/home/ec2-user/environment/webApp/app/main/routes.py", line 294, in upload
    aws_access_key_id= credentials.access_key,
AttributeError: 'NoneType' object has no attribute 'access_key'
2022-03-04 19:30:20,517 INFO: Microblog startup [in /home/ec2-user/environment/webApp/app/__init__.py:74]
